<?xml version="1.0" ?>
<mujoco>
  <compiler coordinate="global" angle="radian"/>
  <option gravity="0.0 0.0 -9.81" timestep="0.005"/>
  <asset>
    <mesh file="./mesh_files/mount_plate.stl"/>
    <mesh file="./mesh_files/sla.stl"/>
    <mesh file="./mesh_files/scu.stl"/>
    <mesh file="./mesh_files/pwp.stl"/>
    <mesh file="./mesh_files/mu1.stl"/>
    <mesh file="./mesh_files/mu1.stl"/>
    <mesh file="./mesh_files/ax1_and_vein.stl"/>
    <mesh file="./mesh_files/wing.stl"/>
    <mesh file="./mesh_files/ax3.stl"/>
    <mesh file="./mesh_files/ax4.stl"/>
    <material name="color_0" rgba="1.00 0.33 1.00 1.00"/>
    <material name="color_1" rgba="0.00 0.33 0.50 1.00"/>
    <material name="color_2" rgba="0.00 1.00 1.00 1.00"/>
    <material name="color_3" rgba="0.80 0.80 0.80 0.20"/>
    <material name="color_4" rgba="1.00 0.67 0.00 1.00"/>
    <material name="color_5" rgba="1.00 0.00 0.00 1.00"/>
    <material name="color_6" rgba="0.33 0.67 0.00 1.00"/>
    <material name="color_7" rgba="0.67 0.67 0.50 1.00"/>
    <material name="color_8" rgba="0.67 1.00 1.00 0.20"/>
    <texture name="grid" type="2d" builtin="checker" width="512" height="512" rgb1="0.1 0.2 0.3" rgb2="0.2 0.3 0.4"/>
    <material name="grid" texture="grid" texrepeat="10 10" texuniform="false" reflectance=".2"/>
  </asset>
  <worldbody>
    <geom name="floor" type="plane" material="grid" condim="3" size="2800.0000000000027 2800.0000000000027 0.05"/>
    <light name="spotlight" mode="targetbodycom" diffuse="0.8 0.8 0.8" specular="0.2 0.2 0.2" pos="368.08486282771526 74.88731191963944 420.00000000000045" cutoff="560.0000000000006" target="mount_plate_001"/>
    <body name="mount_plate_001" pos="0.0 0.0 0.0" quat="1.0 0.0 0.0 0.0">
      <geom name="mount_plate_001_mesh" type="mesh" mesh="mount_plate" material="color_3" pos="0.0 0.0 0.0" quat="1.0 0.0 0.0 0.0"/>
      <freejoint name="mount_plate_001_joint"/>
      <body name="sla_001" pos="-0.500000000000266 19.99999999379196 233.72669307513883" quat="6.317222293885728e-09 0.7071067855762254 -0.7071067767968696 6.317220958106056e-09">
        <geom name="sla_001_mesh" type="mesh" mesh="sla" material="color_4" pos="-0.500000000000266 19.99999999379196 233.72669307513883" quat="6.317222293885728e-09 0.7071067855762254 -0.7071067767968696 6.317220958106056e-09"/>
        <joint name="sla_001_joint" type="hinge" pos="-0.500000000000266 19.99999999379196 233.72669307513883" axis="1.0 0.0 0.0" limited="false" springref="0"/>
        <body name="mu1_002" pos="29.49820738112286 -10.00520945856499 233.03489034965875" quat="0.5742176882893388 -0.000142483490500572 0.8187026420876016 -9.99644094800339e-05">
          <geom name="mu1_002_mesh" type="mesh" mesh="mu1" material="color_2" pos="29.49820738112286 -10.00520945856499 233.03489034965875" quat="0.5742176882893388 -0.000142483490500572 0.8187026420876016 -9.99644094800339e-05" density="0.001"/>
          <joint name="mu1_002_joint_axis1" type="hinge" pos="29.49820738112286 -10.00520945856499 233.03489034965875" axis="1.0 1.2415884083011619e-08 -2.222044605562574e-15" limited="false" springref="0"/>
          <joint name="mu1_002_joint_axis2" type="hinge" pos="29.49820738112286 -10.00520945856499 233.03489034965875" axis="1.2415884003197061e-08 -0.9999999999999998 1.7867801000000004e-08" limited="false" springref="0"/>
        </body>
        <body name="ax3_001" pos="30.06545844965662 -0.00125081271828526 233.7258780996269" quat="0.890161215478691 0.014352641420238496 0.17423841823320022 -0.4207707044856546">
          <geom name="ax3_001_mesh" type="mesh" mesh="ax3" material="color_1" pos="30.06545844965662 -0.00125081271828526 233.7258780996269" quat="0.890161215478691 0.014352641420238496 0.17423841823320022 -0.4207707044856546" density="0.001"/>
          <joint name="ax3_001_joint_axis1" type="hinge" pos="30.06545844965662 -0.00125081271828526 233.7258780996269" axis="1.2415884003197061e-08 -0.9999999999999998 1.7867801000000004e-08" limited="false" springref="0"/>
          <joint name="ax3_001_joint_axis2" type="hinge" pos="30.06545844965662 -0.00125081271828526 233.7258780996269" axis="-1.778155455961102e-15 -1.7867801000000024e-08 -1.0" limited="false" springref="0"/>
          <body name="ax4_001" pos="32.87437538414779 -3.57676909474147 232.17702152411871" quat="0.8901607787611101 0.014352506547432912 0.1742385152818912 -0.4207715927954051">
            <geom name="ax4_001_mesh" type="mesh" mesh="ax4" material="color_7" pos="32.87437538414779 -3.57676909474147 232.17702152411871" quat="0.8901607787611101 0.014352506547432912 0.1742385152818912 -0.4207715927954051" density="0.001"/>
            <joint name="ax4_001_joint" type="slide" pos="32.87437538414779 -3.57676909474147 232.17702152411871" axis="0.5851859757164767 -0.7441059604084896 -0.3222789063983474" limited="false" springref="0"/>
          </body>
        </body>
      </body>
      <body name="scu_001" pos="-0.500000017829198 -19.999999997562195 263.66919307866766" quat="0.5000000044604502 -0.4999999992360228 0.5000000007639748 0.4999999955395524">
        <geom name="scu_001_mesh" type="mesh" mesh="scu" material="color_5" pos="-0.500000017829198 -19.999999997562195 263.66919307866766" quat="0.5000000044604502 -0.4999999992360228 0.5000000007639748 0.4999999955395524"/>
        <joint name="scu_001_joint" type="slide" pos="-0.500000017829198 -19.999999997562195 263.66919307866766" axis="0.0 0.0 1.0" limited="false" springref="0"/>
        <body name="mu1_001" pos="29.49940094521707 -20.000217147111762 233.03415062301033" quat="0.5737503098224159 -0.0034526371592568162 0.819017613718542 0.0029681128876138706">
          <geom name="mu1_001_mesh" type="mesh" mesh="mu1" material="color_2" pos="29.49940094521707 -20.000217147111762 233.03415062301033" quat="0.5737503098224159 -0.0034526371592568162 0.819017613718542 0.0029681128876138706" density="0.001"/>
          <joint name="mu1_001_joint_axis1" type="hinge" pos="29.49940094521707 -20.000217147111762 233.03415062301033" axis="1.0 -1.0448849591115916e-08 7.3929458666022185e-09" limited="false" springref="0"/>
          <joint name="mu1_001_joint_axis2" type="hinge" pos="29.49940094521707 -20.000217147111762 233.03415062301033" axis="1.0448849840916097e-08 1.0000000000000002 5.079270337660091e-15" limited="false" springref="0"/>
        </body>
      </body>
      <body name="pwp_001" pos="-0.49999998225544906 -15.020000000570048 191.9658069223799" quat="0.5000000024124049 0.500000003937422 -0.49999999606258205 0.49999999758759106">
        <geom name="pwp_001_mesh" type="mesh" mesh="pwp" material="color_0" pos="-0.49999998225544906 -15.020000000570048 191.9658069223799" quat="0.5000000024124049 0.500000003937422 -0.49999999606258205 0.49999999758759106" density="0.001"/>
        <body name="ax1_and_vein_001" pos="34.50313945072931 -15.014127937315767 226.9652895772066" quat="0.9999999866587755 -2.6954432318285984e-05 -1.5486013498725162e-05 -0.00016036237389150838">
          <geom name="ax1_and_vein_001_mesh" type="mesh" mesh="ax1_and_vein" material="color_6" pos="34.50313945072931 -15.014127937315767 226.9652895772066" quat="0.9999999866587755 -2.6954432318285984e-05 -1.5486013498725162e-05 -0.00016036237389150838" density="0.001"/>
          <joint name="ax1_and_vein_001_joint_alpha" type="hinge" pos="34.50313945072931 -15.014127937315767 226.9652895772066" axis="1.0 3.050025926265576e-09 -1.269965427264097e-08" limited="false"/>
          <joint name="ax1_and_vein_001_joint_phi" type="hinge" pos="34.50313945072931 -15.014127937315767 226.9652895772066" axis="-3.0500261205546053e-09 1.0 8.132383655379272e-15" limited="false"/>
          <joint name="ax1_and_vein_001_joint_theta" type="hinge" pos="34.50313945072931 -15.014127937315767 226.9652895772066" axis="1.2699653995085214e-08 -8.215650381887537e-15 1.0" limited="false"/>
          <body name="wing_001" pos="44.50273783560285 -15.017567690487594 227.53318386836963" quat="2.642260117382692e-05 0.9999999827467686 -0.00018343465725804894 1.265049681703034e-05">
            <geom name="wing_001_mesh" type="mesh" mesh="wing" material="color_8" pos="44.50273783560285 -15.017567690487594 227.53318386836963" quat="2.642260117382692e-05 0.9999999827467686 -0.00018343465725804894 1.265049681703034e-05" density="0.001"/>
          </body>
        </body>
      </body>
    </body>
  </worldbody>
  <equality>
    <connect body1="mu1_001" body2="ax1_and_vein_001" anchor="27.705895279711935 -20.011886967452924 228.1003485620691" solimp="1.0 1.0 0.001 0.5 2.0"/>
    <connect body1="mu1_002" body2="ax1_and_vein_001" anchor="27.70910253549531 -10.011887496305569 228.0998095230974" solimp="1.0 1.0 0.001 0.5 2.0"/>
    <connect body1="ax4_001" body2="ax1_and_vein_001" anchor="41.30335164661235 -14.298778301741002 227.53296156863001" solimp="1.0 1.0 0.001 0.5 2.0"/>
  </equality>
  <actuator>
    <position name="sla_001_position" joint="sla_001_joint" gear="1" forcelimited="false" ctrllimited="false" kp="6.0e11"/>
    <velocity name="sla_001_velocity" joint="sla_001_joint" gear="1" forcelimited="false" ctrllimited="false" kv="1.0e10"/>
    <position name="scu_001_position" joint="scu_001_joint" gear="1" forcelimited="false" ctrllimited="false" kp="6.0e8"/>
    <velocity name="scu_001_velocity" joint="scu_001_joint" gear="1" forcelimited="false" ctrllimited="false" kv="1.0e8"/>
    <position name="ax4_001_position" joint="ax4_001_joint" gear="1" forcelimited="false" ctrllimited="false" kp="3.0e5"/>
    <velocity name="ax4_001_velocity" joint="ax4_001_joint" gear="1" forcelimited="false" ctrllimited="false" kv="1.0e4"/>
  </actuator>
</mujoco>
