<?xml version="1.0" ?>
<mujoco>
  <compiler coordinate="global" angle="radian"/>
  <option gravity="0.0 0.0 -9.81" timestep="0.005"/>
  <asset>
    <mesh file="./mesh_files/mount_plate.stl"/>
    <mesh file="./mesh_files/sla.stl"/>
    <mesh file="./mesh_files/scu.stl"/>
    <mesh file="./mesh_files/pwp.stl"/>
    <mesh file="./mesh_files/mu1.stl"/>
    <mesh file="./mesh_files/mu1.stl"/>
    <mesh file="./mesh_files/ax1_and_vein.stl"/>
    <mesh file="./mesh_files/wing.stl"/>
    <mesh file="./mesh_files/ax34.stl"/>
    <material name="color_0" rgba="1.00 0.33 1.00 1.00"/>
    <material name="color_1" rgba="0.00 1.00 1.00 1.00"/>
    <material name="color_2" rgba="0.80 0.80 0.80 0.20"/>
    <material name="color_3" rgba="1.00 0.67 0.00 1.00"/>
    <material name="color_4" rgba="0.67 0.67 1.00 1.00"/>
    <material name="color_5" rgba="1.00 0.00 0.00 1.00"/>
    <material name="color_6" rgba="0.33 0.67 0.00 1.00"/>
    <material name="color_7" rgba="0.67 1.00 1.00 0.20"/>
    <texture name="grid" type="2d" builtin="checker" width="512" height="512" rgb1="0.1 0.2 0.3" rgb2="0.2 0.3 0.4"/>
    <material name="grid" texture="grid" texrepeat="10 10" texuniform="false" reflectance=".2"/>
  </asset>
  <worldbody>
    <geom name="floor" type="plane" material="grid" condim="3" size="2800.0000000000027 2800.0000000000027 0.05"/>
    <light name="spotlight" mode="targetbodycom" diffuse="0.8 0.8 0.8" specular="0.2 0.2 0.2" pos="368.08553012103914 74.89750704458307 420.00000000000045" cutoff="560.0000000000006" target="mount_plate_001"/>
    <body name="mount_plate_001" pos="0.0 0.0 0.0" quat="1.0 0.0 0.0 0.0">
      <geom name="mount_plate_001_mesh" type="mesh" mesh="mount_plate" material="color_2" pos="0.0 0.0 0.0" quat="1.0 0.0 0.0 0.0"/>
      <freejoint name="mount_plate_001_joint"/>
      <body name="sla_001" pos="-0.500000000000266 19.99999999379196 233.72669307513883" quat="6.317222293885728e-09 0.7071067855762254 -0.7071067767968696 6.317220958106056e-09">
        <geom name="sla_001_mesh" type="mesh" mesh="sla" material="color_3" pos="-0.500000000000266 19.99999999379196 233.72669307513883" quat="6.317222293885728e-09 0.7071067855762254 -0.7071067767968696 6.317220958106056e-09"/>
        <joint name="sla_001_joint" type="hinge" pos="-0.500000000000266 19.99999999379196 233.72669307513883" axis="1.0 0.0 0.0" limited="false" springref="0"/>
        <body name="mu1_002" pos="29.497664242383156 -10.005097269695945 233.0351722957893" quat="0.5743397002796599 -0.00014083788730550343 0.8186170527637646 -9.885205160003498e-05">
          <geom name="mu1_002_mesh" type="mesh" mesh="mu1" material="color_1" pos="29.497664242383156 -10.005097269695945 233.0351722957893" quat="0.5743397002796599 -0.00014083788730550343 0.8186170527637646 -9.885205160003498e-05" density="0.001"/>
          <joint name="mu1_002_joint_axis1" type="hinge" pos="29.497664242383156 -10.005097269695945 233.0351722957893" axis="1.0 1.2415884083011619e-08 -2.222044605562574e-15" limited="false" springref="0"/>
          <joint name="mu1_002_joint_axis2" type="hinge" pos="29.497664242383156 -10.005097269695945 233.0351722957893" axis="1.2415884003197061e-08 -0.9999999999999998 1.7867801000000004e-08" limited="false" springref="0"/>
        </body>
        <body name="ax34_001" pos="30.06773295117326 -0.000459224676007 233.7265338562808" quat="0.8901858792560381 -0.0009718179492271362 0.1815631780668388 -0.4178552001750099">
          <geom name="ax34_001_mesh" type="mesh" mesh="ax34" material="color_4" pos="30.06773295117326 -0.000459224676007 233.7265338562808" quat="0.8901858792560381 -0.0009718179492271362 0.1815631780668388 -0.4178552001750099" density="0.001"/>
          <joint name="ax34_001_joint_axis1" type="hinge" pos="30.06773295117326 -0.000459224676007 233.7265338562808" axis="1.2415884003197061e-08 -0.9999999999999998 1.7867801000000004e-08" limited="false" springref="0"/>
          <joint name="ax34_001_joint_axis2" type="hinge" pos="30.06773295117326 -0.000459224676007 233.7265338562808" axis="-1.778155455961102e-15 -1.7867801000000024e-08 -1.0" limited="false" springref="0"/>
        </body>
      </body>
      <body name="scu_001" pos="-0.500000053237221 -19.999999997908834 263.6691929812606" quat="0.5000000044604502 -0.4999999992360228 0.5000000007639748 0.4999999955395524">
        <geom name="scu_001_mesh" type="mesh" mesh="scu" material="color_5" pos="-0.500000053237221 -19.999999997908834 263.6691929812606" quat="0.5000000044604502 -0.4999999992360228 0.5000000007639748 0.4999999955395524"/>
        <joint name="scu_001_joint" type="slide" pos="-0.500000053237221 -19.999999997908834 263.6691929812606" axis="0.0 0.0 1.0" limited="false" springref="0"/>
        <body name="mu1_001" pos="29.499392090101136 -20.0002069746251 233.03428118542766" quat="0.5737853990840083 -0.0034357483493890222 0.818993059197234 0.002980003027023033">
          <geom name="mu1_001_mesh" type="mesh" mesh="mu1" material="color_1" pos="29.499392090101136 -20.0002069746251 233.03428118542766" quat="0.5737853990840083 -0.0034357483493890222 0.818993059197234 0.002980003027023033" density="0.001"/>
          <joint name="mu1_001_joint_axis1" type="hinge" pos="29.499392090101136 -20.0002069746251 233.03428118542766" axis="1.0 -1.0448849591115916e-08 7.3929458666022185e-09" limited="false" springref="0"/>
          <joint name="mu1_001_joint_axis2" type="hinge" pos="29.499392090101136 -20.0002069746251 233.03428118542766" axis="1.0448849840916097e-08 1.0000000000000002 5.079270337660091e-15" limited="false" springref="0"/>
        </body>
      </body>
      <body name="pwp_001" pos="-0.499999947014883 -15.020000000187867 191.96580701923233" quat="0.5000000024124049 0.500000003937422 -0.49999999606258205 0.49999999758759106">
        <geom name="pwp_001_mesh" type="mesh" mesh="pwp" material="color_0" pos="-0.499999947014883 -15.020000000187867 191.96580701923233" quat="0.5000000024124049 0.500000003937422 -0.49999999606258205 0.49999999758759106" density="0.001"/>
        <body name="ax1_and_vein_001" pos="34.5029564039759 -15.014178670239906 226.96481892288068" quat="0.9999999876351574 -3.0164788816488855e-05 -5.585028804375175e-06 -0.00015423546344481165">
          <geom name="ax1_and_vein_001_mesh" type="mesh" mesh="ax1_and_vein" material="color_6" pos="34.5029564039759 -15.014178670239906 226.96481892288068" quat="0.9999999876351574 -3.0164788816488855e-05 -5.585028804375175e-06 -0.00015423546344481165" density="0.001"/>
          <joint name="ax1_and_vein_001_joint_alpha" type="hinge" pos="34.5029564039759 -15.014178670239906 226.96481892288068" axis="1.0 3.050025926265576e-09 -1.269965427264097e-08" limited="false"/>
          <joint name="ax1_and_vein_001_joint_phi" type="hinge" pos="34.5029564039759 -15.014178670239906 226.96481892288068" axis="-3.0500261205546053e-09 1.0 8.132383655379272e-15" limited="false"/>
          <joint name="ax1_and_vein_001_joint_theta" type="hinge" pos="34.5029564039759 -15.014178670239906 226.96481892288068" axis="1.2699653995085214e-08 -8.215650381887537e-15 1.0" limited="false"/>
          <body name="wing_001" pos="44.50313711938989 -15.009243117874439 227.5289289091552" quat="3.0093377799482316e-05 0.9999999808312401 -0.00019229101378140753 2.1355892034740793e-05">
            <geom name="wing_001_mesh" type="mesh" mesh="wing" material="color_7" pos="44.50313711938989 -15.009243117874439 227.5289289091552" quat="3.0093377799482316e-05 0.9999999808312401 -0.00019229101378140753 2.1355892034740793e-05" density="0.001"/>
          </body>
        </body>
      </body>
    </body>
  </worldbody>
  <equality>
    <connect body1="mu1_001" body2="ax1_and_vein_001" anchor="27.705795951501493 -20.012013702740223 228.10004458947506" solimp="1.0 1.0 0.001 0.5 2.0"/>
    <connect body1="mu1_002" body2="ax1_and_vein_001" anchor="27.70888066410167 -10.012014196710076 228.0994413109344" solimp="1.0 1.0 0.001 0.5 2.0"/>
    <connect body1="ax34_001" body2="ax1_and_vein_001" anchor="41.30317107442903 -14.298742067655363 227.53235165624176" solimp="1.0 1.0 0.001 0.5 2.0"/>
  </equality>
  <actuator>
    <position name="sla_001_position" joint="sla_001_joint" gear="1" forcelimited="false" ctrllimited="false" kp="6.0e11"/>
    <velocity name="sla_001_velocity" joint="sla_001_joint" gear="1" forcelimited="false" ctrllimited="false" kv="1.0e10"/>
    <position name="scu_001_position" joint="scu_001_joint" gear="1" forcelimited="false" ctrllimited="false" kp="6.0e8"/>
    <velocity name="scu_001_velocity" joint="scu_001_joint" gear="1" forcelimited="false" ctrllimited="false" kv="1.0e8"/>
  </actuator>
</mujoco>
